<?xml version="1.0"?>
<robot xmlns:xacro="http://www.ros.org/wiki/xacro" name="myrobot"> 

   
  <xacro:include filename="$(find description_pkg)/urdf/material.xacro"/>
  
	<xacro:include filename="$(find realsense_gazebo_plugin)/urdf/realsense-RS200.macro.xacro"/>
	 <xacro:realsense-rs200 prefix="" parent="chassis">
        <origin xyz="-0.225 0.0 1.165" rpy="0 0 0" />   
    </xacro:realsense-rs200>
    
  <xacro:include filename="$(find description_pkg)/urdf/plugin.gazebo"/>
 

  <link name="base_link">
  </link>
   <joint name="joint_base" type="fixed">
        <parent link="base_link"/>
        <child link="chassis"/>
        <origin xyz="0.0 0.0 0.010" rpy="0.0 0.0 0.0"/>
  </joint>


  <!-- CHASSIS LINK -->
  <link name="chassis">
        <inertial>
            <origin xyz="0.0 0.0 0.0"/>
            <mass value="20"/>
            <inertia ixx="0.1" ixy="0.0" ixz="0.0" iyy="0.1" iyz="0.0" izz="0.1"/>
        </inertial>
        <visual name='1'>
            <origin xyz="0.0 0.0 0.2" />
            <geometry>
                <box size="0.6 0.45 0.15"/>
            </geometry>
            <material name="white"/>
        </visual>
        <collision name='1'>
            <origin xyz="0.0 0.0 0.2" rpy="0.0 0.0 0.0"/>
            <geometry>
                <box size="0.6 0.45 0.15"/>
            </geometry>
        </collision>
        <visual name='2'>
            <origin xyz="-0.275 0.0 0.7" rpy="0.0 0.0 0.0"/>
            <geometry>
                <box size="0.05 0.45 1.0"/>
            </geometry>
            <material name="white"/>
        </visual>
        <collision name='2'>
            <origin xyz="0.0 0.0 0.0" rpy="0.0 0.0 0.0"/>
            <geometry>
                <box size="0.0 0.0 0.0"/>
            </geometry>
        </collision>
  </link>
  
  <!-- FRONT RIGHT WHEEL LINK   -->
  <link name="front_left_wheel">    
    <inertial>
      <origin rpy="0 0 0 " xyz="0 0 0"/>
      <mass value="0.7"/>
      <inertia ixx="0.1" ixy="0" ixz="0" iyy="0.1" iyz="0" izz="0.1"/>
    </inertial> 
    <collision name="front_left_wheel_collision">
      <origin rpy="0 1.5707 1.5707" xyz="0 0 0" />
      <geometry>
        <cylinder length="0.04" radius="0.1"/>
      </geometry>
    </collision> 
    <visual name="front_left_wheel_visual">
      <origin rpy="0 1.5707 1.5707" xyz="0 0 0"/>
      <geometry>
        <cylinder length="0.05" radius="0.1"/>
      </geometry>
      <material name="Black"/>      
    </visual> 
  </link>
  <joint name="joint_front_left_wheel" type="continuous">
    <origin rpy="0 0 0" xyz="0.175 0.25 0.1"/>
    <child link="front_left_wheel" />
    <parent link="chassis"/>
    <axis rpy="0 0 0" xyz="0 1 0"/>
  </joint>  

  <!-- BACk RIGHT WHEEL LINK    -->
  <link name="back_left_wheel">    
    <inertial>
      <mass value="0.7"/>
      <origin rpy="0 0 0" xyz="0 0 0"/>
      <inertia ixx="0.1" ixy="0" ixz="0" iyy="0.1" iyz="0" izz="0.1"/>
    </inertial> 
    <collision name="back_left_wheel_collision">
      <origin rpy="0 1.5707 1.5707" xyz="0 0 0" />
      <geometry>
        <cylinder length="0.04" radius="0.1"/>
      </geometry>
    </collision> 
    <visual name="back_left_wheel_visual">
      <origin rpy="0 1.5707 1.5707" xyz="0 0 0"/>
      <geometry>
        <cylinder length="0.05" radius="0.1"/>
      </geometry>  
      <material name="Black"/>    
    </visual>   
  </link> 
  <joint name="joint_back_left_wheel" type="continuous">
    <origin rpy="0 0 0" xyz="-0.175 0.25 0.1"/>
    <child link="back_left_wheel" />
    <parent link="chassis"/>
    <axis rpy="0 0 0" xyz="0 1 0"/>
  </joint> 


  <!-- FRONT LEFTT WHEEL LINK   -->
  <link name="front_right_wheel">    
    <inertial>
      <mass value="0.7"/>
      <origin rpy="0 0 0" xyz="0 0 0"/>
      <inertia ixx="0.1" ixy="0" ixz="0" iyy="0.1" iyz="0" izz="0.1"/>
    </inertial> 
    <collision name="front_right_wheel_collision">
      <origin rpy="0 1.5707 1.5707" xyz="0 0 0" />
      <geometry>
        <cylinder length="0.05" radius="0.1"/>
      </geometry>
    </collision>   
    <visual name="front_right_wheel_visual">
      <origin rpy="0 1.5707 1.5707" xyz="0 0 0"/>
      <geometry>
        <cylinder length="0.05" radius="0.1"/>
      </geometry>   
      <material name="Black"/>   
    </visual> 
  </link>
  <joint name="joint_front_right_wheel" type="continuous">
    <origin rpy="0 0 0" xyz="0.175 -0.25 0.10"/>
    <child link="front_right_wheel" />
    <parent link="chassis"/>
    <axis rpy="0 0 0" xyz="0 1 0"/>
  </joint>   

<!-- BACk RIGHT WHEEL LINK    -->
  <link name="back_right_wheel">    
    <inertial>
      <mass value="0.7"/>
      <origin rpy="0 0 0" xyz="0 0 0"/>
      <inertia ixx="0.1" ixy="0" ixz="0" iyy="0.1" iyz="0" izz="0.1"/>
    </inertial>
    
    <collision name="back_right_wheel_collision">
      <origin rpy="0 1.5707 1.5707" xyz="0 0 0" />
      <geometry>
        <cylinder length="0.04" radius="0.1"/>
      </geometry>
    </collision>
    
    <visual name="back_right_wheel_visual">
      <origin rpy="0 1.5707 1.5707" xyz="0 0 0"/>
      <geometry>
        <cylinder length="0.05" radius="0.1"/>
      </geometry>  
      <material name="Black"/>    
    </visual>   
  </link> 
  <joint name="joint_back_right_wheel" type="continuous">
    <origin rpy="0 0 0" xyz="-0.175 -0.25 0.10"/>
    <child link="back_right_wheel" />
    <parent link="chassis"/>
    <axis rpy="0 0 0" xyz="0 1 0"/>
  </joint> 

   
  <!-- LIDAR LINK -->
  <link name="lidar">
    <inertial>
       <origin xyz="0.0 0.0 0.0" rpy="0.0 0.0 0.0"/>
      <mass value="0.9"/>
      <inertia ixx="1.0" ixy="0.0" ixz="0.0" iyy="1.0" iyz="0.0" izz="1.0"/>
    </inertial>
    <visual>
      <origin xyz=" 0 0 0" rpy="0 0 0"/>
      <geometry>
        <mesh filename="package:// description_pkg/meshes/hokuyo.dae"/>       
      </geometry>
    </visual>
    <collision>
      <origin xyz="0.0 0.0 0.0" rpy="0.0 0.0 0.0"/>
      <geometry>
        <mesh filename="package:// description_pkg/meshes/hokuyo.dae" />
       </geometry>  
    </collision>
    </link>
  
    <joint name="lider_joint" type="fixed">
        <origin xyz="0.0 0.0 0.304" rpy="0 0 0"/>
        <parent link="chassis"/>
        <child link="lidar"/>
        <axis xyz="0 0 0" />
    </joint>



</robot>


